<?xml version="1.0"?>
<robot name="S_nula">

<material name="blue">
    <color rgba="0 0 0.8 1"/>
  </material>
  <material name="black">
    <color rgba="0 0 0 1"/>
  </material>
  <material name="white">
    <color rgba="1 1 1 1"/>
  </material>
  
<!-- base -->
  <link name="base_link">
    <visual>
      <geometry>
        <cylinder length="0.6" radius="0.2"/>
      </geometry>
      <material name="blue"/>
      <collision>
      <geometry>
        <cylinder length="0.6" radius="0.2"/>
      </geometry>
    </collision>
    </visual>
  </link>
  
<!-- first link -->
  <link name="first_link">
    <visual>
      <geometry>
        <box size="0.6 0.1 0.1"/>
      </geometry>
      <origin rpy="0 1.57075 0" xyz="0 0 0.3"/>
    </visual>
    <collision>
      <geometry>
        <box size="0.6 0.1 0.1"/>
      </geometry>
      <origin rpy="0 1.57075 0" xyz="0 0 0.3"/>
    </collision>
  </link>
  
<!--first join between ___ -->
  <joint name="base_to_first_link" type="continuous">
    <axis rpy="0 0 0" xyz="0 0 1"/>
    <parent link="base_link"/>
    <child link="first_link"/>
    <origin xyz="0.0 -0.0067 0.32"/>
  </joint>

<link name="second_link">
    <visual>
      <geometry>
        <cylinder length="0.1" radius="0.2"/>
      </geometry>
      <material name="white"/>
      <origin rpy="0 1.57075 0" xyz="0 0 0"/>
    </visual>
    <collision>
      <geometry>
        <cylinder length="0.1" radius="0.2"/>
      </geometry>
    </collision>
  </link>

<!--second join between ___ -->
<joint name="base_to_second" type="continuous">
    <axis rpy="0 0 0" xyz="1 0 0"/>
    <parent link="base_link"/>
    <child link="second_link"/>
    <origin xyz="0.25 0.0 0.15"/>
  </joint>

<!-- third link -->
  <link name="third_link">
    <visual>
      <geometry>
        <box size="0.6 0.1 0.1"/>
      </geometry>
      <origin rpy="0 1.57075 0" xyz="0 0 0.20"/>
    </visual>
    <collision>
      <geometry>
        <box size="0.6 0.1 0.1"/>
      </geometry>
      <origin rpy="0 1.57075 0" xyz="0 0 0.20"/>
    </collision>
  </link>

  <joint name="first_link_to_third_link" type="continuous">
    <axis rpy="0 0 0" xyz="0 1 0"/>
    <parent link="first_link"/>
    <child link="third_link"/>
    <origin xyz="0.0 0.1 0.54"/>
  </joint>


</robot>
